<mujoco model="KukaLbrIiwa">
  <compiler angle="radian" strippath="true" assetdir="meshes" autolimits="true"/>
  <option impratio="10"/>
  <!-- <option gravity="0 0 10"/> -->
  <statistic extent="1.5" meansize=".05"/>

  <option timestep="0.001" jacobian="sparse" integrator="RK4"/>

  <!--keyframe>
      <!key time="0" qpos="0 0 0 0 0 0 0  0 0 0 0 0 0 0 0   0 0 0 0 0 0 0" />
      <key time="0" qpos="0 0 0 0 0 0 0  0 0 0 0 0 0 0" />
  </keyframe-->

  <actuator>
    <motor ctrllimited="true" ctrlrange="-320.0 320.0" joint="iiwa_joint_1" name="torq_j1"/>
    <motor ctrllimited="true" ctrlrange="-320.0 320.0" joint="iiwa_joint_2" name="torq_j2"/>
    <motor ctrllimited="true" ctrlrange="-176.0 176.0" joint="iiwa_joint_3" name="torq_j3"/>
    <motor ctrllimited="true" ctrlrange="-176.0 176.0" joint="iiwa_joint_4" name="torq_j4"/>
    <motor ctrllimited="true" ctrlrange="-110.0 110.0" joint="iiwa_joint_5" name="torq_j5"/>
    <motor ctrllimited="true" ctrlrange="-40.0 40.0" joint="iiwa_joint_6" name="torq_j6"/>
    <motor ctrllimited="true" ctrlrange="-40.0 40.0" joint="iiwa_joint_7" name="torq_j7"/>
  </actuator>

  <asset>
    <mesh name="link_0" file="base_link.stl"/>
    <mesh name="link_1" file="link_1.stl"/>
    <mesh name="link_2" file="link_2.stl"/>
    <mesh name="link_3" file="link_3.stl"/>
    <mesh name="link_4" file="link_4.stl"/>
    <mesh name="link_5" file="link_5.stl"/>
    <mesh name="link_6" file="link_6.stl"/>
    <mesh name="link_7" file="link_7.stl"/>

    <material name="metal" rgba="0.58 0.58 0.58 1"/>
    <material name="silicone" rgba="0.1882 0.1882 0.1882 1"/>
    <material name="gray" rgba="0.4627 0.4627 0.4627 1"/>
    <material name="black" rgba="0.149 0.149 0.149 1"/>
    <material name="wood" rgba="0.56 0.37 0.29 1"/>
    <material name="matplane" reflectance="0.3" texture="texplane" texrepeat="1 1" texuniform="true"/>

    <texture type="skybox" builtin="gradient" rgb1="0.3 0.5 0.7" rgb2="0 0 0" width="512"
      height="512"/>

    <texture name="texplane" type="2d" builtin="checker" rgb1=".2 .3 .4" rgb2=".1 0.15 0.2"
      width="512" height="512" mark="cross" markrgb=".8 .8 .8"/>
  </asset>

  <worldbody>
    <light directional="true" diffuse=".4 .4 .4" specular="0.1 0.1 0.1" pos="0 0 5.0" dir="0 0 -1"
      castshadow="false"/>
    <light directional="true" diffuse=".6 .6 .6" specular="0.2 0.2 0.2" pos="0 0 4" dir="0 0 -1"/>

    <geom name="ground" type="plane" size="0 0 1" pos="0 0 0" quat="1 0 0 0" material="matplane"
      condim="1"/>

    <body name="iiwa_base" pos="0 0 0">
      <!-- robot view -->
      <camera mode="fixed" name="robotview" pos="1.0 0 0.4" quat="0.653 0.271 0.271 0.653"/>

      <inertial diaginertia="0 0 0" mass="0" pos="0 0 0"/>

      <geom type="mesh" contype="0" conaffinity="0" group="1" density="0" mesh="link_0"
        rgba="0.4 0.4 0.4 1"/>
      <geom type="mesh" mesh="link_0" rgba="0.4 0.4 0.4 1"/>

      <body name="iiwa_link_1" pos="0 0 0.1525">
        <inertial pos="0 -0.01439 0.102503" quat="1 0 0 0" mass="6.495"
          diaginertia="0.0690761441316632 0.0711085586914514 0.0200625854402119"/>

        <joint name="iiwa_joint_1" pos="0 0 0" axis="0 0 1" damping="0.0" limited="true"
          range="-2.96706 2.96706"/>

        <geom type="mesh" contype="0" conaffinity="0" group="1" density="0" mesh="link_1"
          rgba="0.4 0.4 0.4 1"/>
        <geom type="mesh" mesh="link_1" rgba="0.4 0.4 0.4 1"/>

        <body name="iiwa_link_2" pos="0 0 0.2075" quat="0 0 0.707107 0.707107">
          <inertial pos="1.2e-05 0.06472 0.004804" quat="1 0 0 0" mass="8.807"
            diaginertia="0.0824701683534692 0.0164110968055191 0.0873510892661361"/>

          <joint name="iiwa_joint_2" pos="0 0 0" axis="0 0 1" damping="0.0" limited="true"
            range="-2.0944 2.0944"/>

          <geom pos="0 0 -0.013" quat="0 0 0 1" type="mesh" contype="0" conaffinity="0" group="1"
            density="0" mesh="link_2" rgba="0.4 0.4 0.4 1"/>
          <geom pos="0 0 -0.013" quat="0 0 0 1" type="mesh" mesh="link_2" rgba="0.4 0.4 0.4 1"/>

          <body name="iiwa_link_3" pos="0 0.2325 0" quat="0 0 0.707107 0.707107">
            <inertial pos="-0.000208 0.01601 0.087283" quat="1 0 0 0" mass="2.8"
              diaginertia="0.0230152941318817 0.0228661554143474 0.0454482283748983"/>

            <joint name="iiwa_joint_3" pos="0 0 0" axis="0 0 1" damping="0.0" limited="true"
              range="-2.96706 2.96706"/>

            <geom type="mesh" contype="0" conaffinity="0" group="1" density="0" mesh="link_3"
              rgba="0.4 0.4 0.4 1"/>
            <geom type="mesh" mesh="link_3" rgba="0.4 0.4 0.4 1"/>

            <body name="iiwa_link_4" pos="0 0 0.1875" quat="0.707107 0.707107 0 0">
              <inertial pos="-0.000203 0.098639 0.011478" quat="1 0 0 0" mass="5.283"
                diaginertia="0.0472789668341968 0.00964726804146909 0.0466529007761679"/>

              <joint name="iiwa_joint_4" pos="0 0 0" axis="0 0 1" damping="0.0" limited="true"
                range="-2.0944 2.0944"/>

              <geom pos="0 0 -0.011" type="mesh" contype="0" conaffinity="0" group="1" density="0"
                mesh="link_4" rgba="0.4 0.4 0.4 1"/>
              <geom pos="0 0 -0.011" type="mesh" mesh="link_4" rgba="0.4 0.4 0.4 1"/>

              <body name="iiwa_link_5" pos="0 0.2125 0" quat="0 0 0.707107 0.707107">
                <inertial pos="5.7e-05 0.014468 0.062938" mass="1.889"
                  diaginertia="0.0138359953358589 0.0116859337751969 0.00571863785412578"/>

                <joint name="iiwa_joint_5" pos="0 0 0" axis="0 0 1" damping="0.0" limited="true"
                  range="-2.96706 2.96706"/>

                <geom quat="0 0 0 1" type="mesh" contype="0" conaffinity="0" group="1" density="0"
                  mesh="link_5" rgba="0.4 0.4 0.4 1"/>
                <geom quat="0 0 0 1" type="mesh" mesh="link_5" rgba="0.4 0.4 0.4 1"/>

                <body name="iiwa_link_6" pos="0 0 0.1875" quat="0.707107 0.707107 0 0">
                  <inertial pos="0.000363 0.016982 -0.019731" quat="1 0 0 0" mass="2.32"
                    diaginertia="0.00732758787216765 0.00477633755783711 0.00606797638550296"/>

                  <joint name="iiwa_joint_6" pos="0 0 0" axis="0 0 1" damping="0.0" limited="true"
                    range="-2.0944 2.0944"/>

                  <geom pos="0 0 -0.061" quat="0 0 0 1" type="mesh" contype="0" conaffinity="0"
                    group="1" density="0" mesh="link_6" rgba="0.4 0.4 0.4 1"/>
                  <geom pos="0 0 -0.061" quat="0 0 0 1" type="mesh" mesh="link_6"
                    rgba="0.4 0.4 0.4 1"/>

                  <body name="iiwa_link_7" pos="0 0.081 0" quat="0 0 0.707107 0.707107">
                    <inertial pos="0.001904 -9.3e-05 0.018862" quat="1 0 0 0" mass="0.863"
                      diaginertia="0.000884 0.000888 0.001105"/>

                    <joint name="iiwa_joint_7" pos="0 0 0" axis="0 0 1" damping="0.0" limited="true"
                      range="-3.05433 3.05433"/>

                    <geom type="mesh" contype="0" conaffinity="0" group="1" density="0"
                      mesh="link_7" rgba="0.4 0.4 0.4 1"/>
                    <geom type="mesh" mesh="link_7" rgba="0.4 0.4 0.4 1"/>
                  </body>
                </body>
              </body>
            </body>
          </body>
        </body>
      </body>
    </body>

    <!--body
    name="cylinder" pos="0.65 0 0.075">
      <freejoint/>
      <geom  type="cylinder" size="0.02 0.075" mass="0.5" material="wood" condim="3" friction="1 0.1
    0.1"/>
    </body-->
  </worldbody>
</mujoco>